Traceback (most recent call last):
  File "c:\Users\qchasserieau\Anaconda3\envs\quetzal_env\lib\site-packages\urllib3\connectionpool.py", line 699, in urlopen
    httplib_response = self._make_request(
  File "c:\Users\qchasserieau\Anaconda3\envs\quetzal_env\lib\site-packages\urllib3\connectionpool.py", line 382, in _make_request
    self._validate_conn(conn)
  File "c:\Users\qchasserieau\Anaconda3\envs\quetzal_env\lib\site-packages\urllib3\connectionpool.py", line 1010, in _validate_conn
    conn.connect()
  File "c:\Users\qchasserieau\Anaconda3\envs\quetzal_env\lib\site-packages\urllib3\connection.py", line 416, in connect
    self.sock = ssl_wrap_socket(
  File "c:\Users\qchasserieau\Anaconda3\envs\quetzal_env\lib\site-packages\urllib3\util\ssl_.py", line 449, in ssl_wrap_socket
    ssl_sock = _ssl_wrap_socket_impl(
  File "c:\Users\qchasserieau\Anaconda3\envs\quetzal_env\lib\site-packages\urllib3\util\ssl_.py", line 493, in _ssl_wrap_socket_impl
    return ssl_context.wrap_socket(sock, server_hostname=server_hostname)
  File "c:\Users\qchasserieau\Anaconda3\envs\quetzal_env\lib\ssl.py", line 500, in wrap_socket
    return self.sslsocket_class._create(
  File "c:\Users\qchasserieau\Anaconda3\envs\quetzal_env\lib\ssl.py", line 1040, in _create
    self.do_handshake()
  File "c:\Users\qchasserieau\Anaconda3\envs\quetzal_env\lib\ssl.py", line 1309, in do_handshake
    self._sslobj.do_handshake()
ssl.SSLCertVerificationError: [SSL: CERTIFICATE_VERIFY_FAILED] certificate verify failed: unable to get local issuer certificate (_ssl.c:1131)

During handling of the above exception, another exception occurred:

Traceback (most recent call last):
  File "c:\Users\qchasserieau\Anaconda3\envs\quetzal_env\lib\site-packages\requests\adapters.py", line 439, in send
    resp = conn.urlopen(
  File "c:\Users\qchasserieau\Anaconda3\envs\quetzal_env\lib\site-packages\urllib3\connectionpool.py", line 755, in urlopen
    retries = retries.increment(
  File "c:\Users\qchasserieau\Anaconda3\envs\quetzal_env\lib\site-packages\urllib3\util\retry.py", line 574, in increment
    raise MaxRetryError(_pool, url, error or ResponseError(cause))
urllib3.exceptions.MaxRetryError: HTTPSConnectionPool(host='overpass-api.de', port=443): Max retries exceeded with url: /api/status (Caused by SSLError(SSLCertVerificationError(1, '[SSL: CERTIFICATE_VERIFY_FAILED] certificate verify failed: unable to get local issuer certificate (_ssl.c:1131)')))

During handling of the above exception, another exception occurred:

Traceback (most recent call last):
  File "c:\Users\qchasserieau\Anaconda3\envs\quetzal_env\lib\site-packages\osmnx\downloader.py", line 320, in _get_pause
    response = requests.get(url, headers=_get_http_headers())
  File "c:\Users\qchasserieau\Anaconda3\envs\quetzal_env\lib\site-packages\requests\api.py", line 75, in get
    return request('get', url, params=params, **kwargs)
  File "c:\Users\qchasserieau\Anaconda3\envs\quetzal_env\lib\site-packages\requests\api.py", line 61, in request
    return session.request(method=method, url=url, **kwargs)
  File "c:\Users\qchasserieau\Anaconda3\envs\quetzal_env\lib\site-packages\requests\sessions.py", line 542, in request
    resp = self.send(prep, **send_kwargs)
  File "c:\Users\qchasserieau\Anaconda3\envs\quetzal_env\lib\site-packages\requests\sessions.py", line 655, in send
    r = adapter.send(request, **kwargs)
  File "c:\Users\qchasserieau\Anaconda3\envs\quetzal_env\lib\site-packages\requests\adapters.py", line 514, in send
    raise SSLError(e, request=request)
requests.exceptions.SSLError: HTTPSConnectionPool(host='overpass-api.de', port=443): Max retries exceeded with url: /api/status (Caused by SSLError(SSLCertVerificationError(1, '[SSL: CERTIFICATE_VERIFY_FAILED] certificate verify failed: unable to get local issuer certificate (_ssl.c:1131)')))

During handling of the above exception, another exception occurred:

Traceback (most recent call last):
  File "A10_OpenStreetMap.py", line 148, in <module>
    main()
  File "A10_OpenStreetMap.py", line 56, in main
    drive = ox.graph_from_polygon(hull, network_type='drive')
  File "c:\Users\qchasserieau\Anaconda3\envs\quetzal_env\lib\site-packages\osmnx\graph.py", line 420, in graph_from_polygon
    response_jsons = downloader._osm_network_download(poly_buff, network_type, custom_filter)
  File "c:\Users\qchasserieau\Anaconda3\envs\quetzal_env\lib\site-packages\osmnx\downloader.py", line 508, in _osm_network_download
    response_json = overpass_request(data={"data": query_str})
  File "c:\Users\qchasserieau\Anaconda3\envs\quetzal_env\lib\site-packages\osmnx\downloader.py", line 716, in overpass_request
    this_pause = _get_pause(base_endpoint)
  File "c:\Users\qchasserieau\Anaconda3\envs\quetzal_env\lib\site-packages\osmnx\downloader.py", line 327, in _get_pause
    sc = response.status_code
UnboundLocalError: local variable 'response' referenced before assignment
